Workbook

Sheet 안내
A1: 유동성 지표 체계적 문헌고찰 — 담당자(이원석) 작업 파일
A2: 작성 2026-10-13 · 연구책임자 최승비 · 원본 데이터: 저장소 csbee89/literature-review
A4: 시트 안내
A5: 종합148: 이번 리뷰에서 정리할 논문 전체(교수 승인 10/11). 주차·담당·짝·원문 받는 법이 함께 있다.
A6: 주차별배정: 매주 누가 무엇을 하는지. 노란 칸(제출일·접수·짝점검·반려사유)을 원석이 채운다. 맨 위 회색 '예시' 행을 따라 쓴다.
A7: 진행현황: 주차별배정의 노란 칸을 채우면 자동으로 계산된다(수식). 매주 수요일 보고에 이 숫자를 쓴다.
A8: 분류틀: 단계·기능·시장 코드의 뜻과 148편의 교차표(수식).
A9: 선별과정: 52,006건에서 148편이 되기까지(PRISMA). 논문 3장의 숫자.
A10: 전체438: 제목·초록 선별을 통과한 438편과 각 편이 종합/배경/증거지도 중 어디로 갔는지.
A12: 노란 칸 입력 규칙
A13: 접수: O(통과) / 반려 / 미제출 중 하나. 짝점검: O / 수정필요. 반려사유는 짧게(예: 정의 원문 쪽수 없음).
A14: 원문 상태 '도서관 전자저널'은 학교 도서관 로그인 후 DOI 링크로 받는다. 안 되면 상호대차.
... A19: 선별과정 시트의 수치는 저장소 review/prisma_flow.md(2026-10-10 검색 실행 결과)에서 옮긴 값이다.

Sheet 종합148
A1: pid | B1: 주차 | C1: 담당 | D1: 짝 | E1: 연도 | F1: 제목 | G1: 학술지 | H1: DOI | I1: 단계 | J1: 기능 | K1: 시장 | L1: 한국 | M1: 원문 상태 | N1: 원문 받는 법 | O1: 비고
A2: p115 | B2: 예시 | C2: Claude | D2: 이원석 | E2: 2021 | F2: Frequency domain analysis to detect common cycle in housing price and trading volume | G2: Journal of Housing and Urban Finance | H2: https://doi.org/10.38100/jhuf.2021.6.2.53 | I2: S4 체결(거래량·가격 발견) | J2: F3 선행성·관계 | K2: 비MLS 포털·중개 | L2: Y | M2: 받음 | N2: papers/p115.pdf | O2: 정리 예시 완료(examples/example_Ma2021_p115.md). 원석이 원문 대조 검증
A3: p023 | B3: W01 | C3: 전원(파일럿) | D3: 전원 비교 | E3: 2019 | F3: Factors Affecting the Days on Market of Residential Real Estate in Seoul | G3: Korean Association for Housing Policy Studies | H3: https://doi.org/10.24957/hsr.2019.27.1.05 | I3: S3 매칭(매물 시간·호가 조정) | J3: F1 정의·구축 | K3: 비MLS 포털·중개 | L3: Y | M3: 한국 학술지(KCI·RISS·DBpia) | N3: KCI에서 논문명 검색 → 원문보기. 안 되면 RISS·DBpia(학교 계정)
A4: p058 | B4: W02 | C4: 이원석 | D4: 학부④ | E4: 2023 | F4: A Study on the Impact of Asking Price and Sales Volume on the Real Transaction Price of Apartment using Machine Learning | G4: The Journal of Korean Institute of Information Technology | H4: https://doi.org/10.14801/jkiit.2023.21.10.37 | I4: S2 공급·호가 설정 | J4: F3 선행성·관계 | K4: 비MLS 포털·중개 | L4: Y | M4: 한국 학술지(KCI·RISS·DBpia) | N4: KCI에서 논문명 검색 → 원문보기. 안 되면 RISS·DBpia(학교 계정)
A5: p089 | B5: W02 | C5: 박사 | D5: 석사① | E5: 2016 | F5: A study on the impact of changes in consumer sentiment on the housing market in Korea | G5: International Journal of Urban Sciences | H5: https://doi.org/10.1080/12265934.2016.1239548 | I5: S1 수요·관심 | J5: F3 선행성·관계 | K5: 비MLS 포털·중개 | L5: Y | M5: 한국 학술지(KCI·RISS·DBpia) | N5: KCI에서 논문명 검색 → 원문보기. 안 되면 RISS·DBpia(학교 계정)
A6: p092 | B6: W02 | C6: 석사① | D6: 박사 | E6: 2017 | F6: Relationship Among News Coverage, Consumers’ Sentiment, Prices, and Trading Volume in Housing Markets | G6: Korean Association for Housing Policy Studies | H6: https://doi.org/10.24957/hsr.2017.25.3.01 | I6: S1 수요·관심 | J6: F3 선행성·관계 | K6: 비MLS 포털·중개 | L6: Y | M6: 한국 학술지(KCI·RISS·DBpia) | N6: KCI에서 논문명 검색 → 원문보기. 안 되면 RISS·DBpia(학교 계정)
A7: p094 | B7: W02 | C7: 석사② | D7: 학부① | E7: 2018 | F7: A Study on the Effects of News Big Data and Google Information Search on Apartment Transaction Volume | G7: Residential Environment Institute Of Korea | H7: https://doi.org/10.22313/reik.2018.16.2.411 | I7: S1 수요·관심 | J7: F3 선행성·관계 | K7: 비MLS 포털·중개 | L7: Y | M7: 한국 학술지(KCI·RISS·DBpia) | N7: KCI에서 논문명 검색 → 원문보기. 안 되면 RISS·DBpia(학교 계정)
A8: p103 | B8: W02 | C8: 학부① | D8: 석사② | E8: 2019 | F8: Consumer Sentiment in On-line Community and the Variation of Real Estate Market | G8: Residential Environment Institute Of Korea | H8: https://doi.org/10.22313/reik.2019.17.4.31 | I8: S1 수요·관심 | J8: F3 선행성·관계 | K8: 비MLS 포털·중개 | L8: Y | M8: 한국 학술지(KCI·RISS·DBpia) | N8: KCI에서 논문명 검색 → 원문보기. 안 되면 RISS·DBpia(학교 계정)
A9: p109 | B9: W02 | C9: 학부② | D9: 학부③ | E9: 2020 | F9: Big Data Time Series Analysis of the Relationship Between News Coverage, Apartment Price and Trading Volume | G9: Korea Association Of Real Estate Law | H9: https://doi.org/10.32989/rel.2020.24.2.53 | I9: S1 수요·관심 | J9: F3 선행성·관계 | K9: 비MLS 포털·중개 | L9: Y | M9: 한국 학술지(KCI·RISS·DBpia) | N9: KCI에서 논문명 검색 → 원문보기. 안 되면 RISS·DBpia(학교 계정)
A10: p119 | B10: W02 | C10: 학부③ | D10: 학부② | E10: 2023 | F10: Effects of Consumer Sentiment, Interest Rate, and Transaction Volume on Housing Price Using the BVAR | G10: The Journal of Humanities and Social sciences 21 | H10: https://doi.org/10.22143/hss21.14.2.27 | I10: S1 수요·관심 | J10: F3 선행성·관계 | K10: 비MLS 포털·중개 | L10: Y | M10: 한국 학술지(KCI·RISS·DBpia) | N10: KCI에서 논문명 검색 → 원문보기. 안 되면 RISS·DBpia(학교 계정)
A11: p148 | B11: W02 | C11: 학부④ | D11: 이원석 | E11: 2026 | F11: Real Estate News Data by Living District in Seoul Trend Analysis Research Through Topic Modeling and Sentiment Analysis: Focusing on Apartment and Non-Apartment Transaction Volume | G11: 정보과학회 컴퓨팅의 실제 논문지 | H11: https://doi.org/10.5626/ktcp.2026.32.3.89 | I11: S1 수요·관심 | J11: F3 선행성·관계 | K11: 비MLS 포털·중개 | L11: Y | M11: 한국 학술지(KCI·RISS·DBpia) | N11: KCI에서 논문명 검색 → 원문보기. 안 되면 RISS·DBpia(학교 계정)
A12: p025 | B12: W03 | C12: 석사① | D12: 박사 | E12: 2019 | F12: The Effect of Apartment Housing Characteristics on the Days On Market(DOM) | G12: The Korean Association of Urban Policies | H12: https://doi.org/10.21447/jup.2019.10.3.101 | I12: S3 매칭(매물 시간·호가 조정) | J12: F1 정의·구축 | K12: 비MLS 포털·중개 | L12: Y | M12: 한국 학술지(KCI·RISS·DBpia) | N12: KCI에서 논문명 검색 → 원문보기. 안 되면 RISS·DBpia(학교 계정)
A13: p035 | B13: W03 | C13: 석사② | D13: 학부① | E13: 2026 | F13: Determinants of Time to Close in Housing Transactions: Evidence from Survival Analysis | G13: Korean Association for Housing Policy Studies | H13: https://doi.org/10.24957/hsr.2026.34.2.101 | I13: S3 매칭(매물 시간·호가 조정) | J13: F1 정의·구축 | K13: 비MLS 포털·중개 | L13: Y | M13: 한국 학술지(KCI·RISS·DBpia) | N13: KCI에서 논문명 검색 → 원문보기. 안 되면 RISS·DBpia(학교 계정)
A14: p063 | B14: W03 | C14: 박사 | D14: 석사① | E14: 2026 | F14: Does Online Apartment Listing Volume Lead Price Changes?: The Role of Transaction Volume and a Comparison of Sale and Jeonse Markets | G14: Korean Association for Housing Policy Studies | H14: https://doi.org/10.24957/hsr.2026.34.3.267 | I14: S2 공급·호가 설정 | J14: F3 선행성·관계 | K14: 비MLS 포털·중개 | L14: Y | M14: 한국 학술지(KCI·RISS·DBpia) | N14: KCI에서 논문명 검색 → 원문보기. 안 되면 RISS·DBpia(학교 계정)
... A27: p123 | B27: W04 | C27: 이원석 | D27: 학부④ | E27: 2024 | F27: Dynamic Relationship between Housing Sales Price and Transaction Volume by Housing Type in the Metropolitan Area | G27: The Journal of the Korea Contents Association | H27: https://doi.org/10.5392/jkca.2024.24.01.621 | I27: S4 체결(거래량·가격 발견) | J27: F3 선행성·관계 | K27: 비MLS 포털·중개 | L27: Y | M27: 한국 학술지(KCI·RISS·DBpia) | N27: KCI에서 논문명 검색 → 원문보기. 안 되면 RISS·DBpia(학교 계정)
A28: p002 | B28: W05 | C28: 석사② | D28: 박사 | E28: 1988 | F28: The Duration of Marketing Time of Residential Housing | G28: Real Estate Economics | H28: https://doi.org/10.1111/1540-6229.00463 | I28: S3 매칭(매물 시간·호가 조정) | J28: F1 정의·구축 | K28: MLS 시장 | M28: 도서관 전자저널 | N28: 가천대 도서관 로그인 후 DOI 링크로 접속. 구독 안 되면 상호대차 신청
A29: p003 | B29: W05 | C29: 학부① | D29: 학부③ | E29: 1990 | F29: Measuring Residential Real Estate Liquidity | G29: Real Estate Economics | H29: https://doi.org/10.1111/1540-6229.00514 | I29: S3 매칭(매물 시간·호가 조정) | J29: F1 정의·구축 | K29: MLS 시장 | M29: 도서관 전자저널 | N29: 가천대 도서관 로그인 후 DOI 링크로 접속. 구독 안 되면 상호대차 신청
A30: p009 | B30: W05 | C30: 학부② | D30: 석사① | E30: 2010 | F30: Liquidating Real Estate Assets Quickly: What Affects the Probability of a Quick Sale? | G30: Journal of Real Estate Practice and Education | H30: https://doi.org/10.1080/10835547.2010.12091669 | I30: S3 매칭(매물 시간·호가 조정) | J30: F1 정의·구축 | K30: MLS 시장 | M30: 도서관 전자저널 | N30: 가천대 도서관 로그인 후 DOI 링크로 접속. 구독 안 되면 상호대차 신청
A31: p012 | B31: W05 | C31: 학부③ | D31: 이원석 | E31: 2012 | F31: Cross sectional Analysis of time on Market indicators for an Australian City | G31: Pacific Rim Property Research Journal | H31: https://doi.org/10.1080/14445921.2012.11104370 | I31: S3 매칭(매물 시간·호가 조정) | J31: F1 정의·구축 | K31: 비MLS 포털·중개 | M31: 도서관 전자저널 | N31: 가천대 도서관 로그인 후 DOI 링크로 접속. 구독 안 되면 상호대차 신청
A32: p014 | B32: W05 | C32: 학부④ | D32: 석사② | E32: 2012 | F32: Modelling a property's time to sale by inflating its previous selling price | G32: Journal of the Operational Research Society | H32: https://doi.org/10.1057/jors.2011.74 | I32: S3 매칭(매물 시간·호가 조정) | J32: F1 정의·구축 | K32: 비MLS 포털·중개 | M32: 도서관 전자저널 | N32: 가천대 도서관 로그인 후 DOI 링크로 접속. 구독 안 되면 상호대차 신청
A33: p019 | B33: W05 | C33: 이원석 | D33: 학부④ | E33: 2015 | F33: Marketing Time and Sales Price of Residential Properties in Akure, Nigeria | G33: Journal of economics and sustainable development | I33: S3 매칭(매물 시간·호가 조정) | J33: F1 정의·구축 | K33: 비MLS 포털·중개 | M33: 도서관 전자저널 | N33: 가천대 도서관 로그인 후 DOI 링크로 접속. 구독 안 되면 상호대차 신청
A34: p128 | B34: W05 | C34: 박사 | D34: 학부① | E34: 2026 | F34: A Study on the Typology of the Busan Housing Market Considering Price Differentiation and Transaction Liquidity | G34: Korea Real Estate Society | H34: https://doi.org/10.37407/kres.2026.44.3.315 | I34: S5 집계 상태·지수 | J34: F1 정의·구축 | K34: 비MLS 포털·중개 | L34: Y | M34: 한국 학술지(KCI·RISS·DBpia) | N34: KCI에서 논문명 검색 → 원문보기. 안 되면 RISS·DBpia(학교 계정)
A35: p129 | B35: W05 | C35: 석사① | D35: 학부② | E35: 2026 | F35: Apartment Transaction Volume and Price Volatility: Construction and Application of a Transaction-Volume-Based Price Uncertainty Index | G35: Housing Finance Research | H35: https://doi.org/10.52344/hfr.2026.10.1.133 | I35: S5 집계 상태·지수 | J35: F1 정의·구축 | K35: 비MLS 포털·중개 | L35: Y | M35: 받음 | N35: papers/p129.pdf
A36: p004 | B36: W06 | C36: 학부② | D36: 석사① | E36: 1994 | F36: Censored Sample Bias, Macroeconomic Factors, and Time on Market of Residential Housing | G36: Journal of Real Estate Research | H36: https://doi.org/10.1080/10835547.1994.12090750 | I36: S3 매칭(매물 시간·호가 조정) | J36: F2 측정 쟁점 | K36: MLS 시장 | M36: 도서관 전자저널 | N36: 가천대 도서관 로그인 후 DOI 링크로 접속. 구독 안 되면 상호대차 신청
A37: p005 | B37: W06 | C37: 학부③ | D37: 이원석 | E37: 2003 | F37: Exploring Spatial Effects on Urban Housing Duration | G37: Environment and Planning A Economy and Space | H37: https://doi.org/10.1068/a35170 | I37: S3 매칭(매물 시간·호가 조정) | J37: F2 측정 쟁점 | K37: 비MLS 포털·중개 (확인) | M37: 도서관 전자저널 | N37: 가천대 도서관 로그인 후 DOI 링크로 접속. 구독 안 되면 상호대차 신청
A38: p006 | B38: W06 | C38: 학부④ | D38: 석사② | E38: 2006 | F38: Submarket Dynamics of Time to Sale | G38: Real Estate Economics | H38: https://doi.org/10.1111/j.1540-6229.2006.00171.x | I38: S3 매칭(매물 시간·호가 조정) | J38: F2 측정 쟁점 | K38: 비MLS 포털·중개 | M38: 도서관 전자저널 | N38: 가천대 도서관 로그인 후 DOI 링크로 접속. 구독 안 되면 상호대차 신청
A39: p007 | B39: W06 | C39: 이원석 | D39: 학부④ | E39: 2007 | F39: The Probability of Sale for Residential Real Estate | G39: Journal of Housing Research | H39: https://doi.org/10.1080/10835547.2007.12091978 | I39: S3 매칭(매물 시간·호가 조정) | J39: F2 측정 쟁점 | K39: MLS 시장 | M39: 도서관 전자저널 | N39: 가천대 도서관 로그인 후 DOI 링크로 접속. 구독 안 되면 상호대차 신청
A40: p027 | B40: W06 | C40: 석사① | D40: 학부② | E40: 2020 | F40: A hybrid neural network for predicting Days on Market a measure of liquidity in real estate industry | G40: Knowledge-Based Systems | H40: https://doi.org/10.1016/j.knosys.2020.106417 | I40: S3 매칭(매물 시간·호가 조정) | J40: F1 정의·구축 | K40: MLS 시장 (확인) | M40: 도서관 전자저널 | N40: 가천대 도서관 로그인 후 DOI 링크로 접속. 구독 안 되면 상호대차 신청
A41: p028 | B41: W06 | C41: 석사② | D41: 박사 | E41: 2020 | F41: Key determinants of time on the market: an analysis of residential housing market in Sri Lanka | G41: International Journal of Housing Markets and Analysis | H41: https://doi.org/10.1108/ijhma-06-2020-0071 | I41: S3 매칭(매물 시간·호가 조정) | J41: F1 정의·구축 | K41: 비MLS 포털·중개 | M41: 도서관 전자저널 | N41: 가천대 도서관 로그인 후 DOI 링크로 접속. 구독 안 되면 상호대차 신청
A42: p032 | B42: W06 | C42: 학부① | D42: 학부③ | E42: 2022 | F42: The Impacts of Property Features on Time on Market of Real Estate Assets in Lagos Metropolis, Nigeria | G42: UNIOSUN Journal of Engineering and Environmental Sciences | H42: https://doi.org/10.36108/ujees/2202.40.0210 | I42: S3 매칭(매물 시간·호가 조정) | J42: F1 정의·구축 | K42: 비MLS 포털·중개 | M42: 무료 원문(직접 받기) | N42: https://ujees.com.ng/publication/vol_4/issue_2/Article_1.pdf
A43: p105 | B43: W06 | C43: 박사 | D43: 학부① | E43: 2019 | F43: The Repeat Time-On-The-Market Index | G43: Journal of Urban Economics | H43: https://doi.org/10.1016/j.jue.2019.04.005 | I43: S3 매칭(매물 시간·호가 조정) | J43: F1 정의·구축 | K43: MLS 시장 | M43: 도서관 전자저널 | N43: 가천대 도서관 로그인 후 DOI 링크로 접속. 구독 안 되면 상호대차 신청
A44: p008 | B44: W07 | C44: 석사① | D44: 학부② | E44: 2009 | F44: Spatial Heterogeneity in Listing Duration: The Influence of Relative Location to Marketability | G44: Journal of Housing Research | H44: https://doi.org/10.1080/10835547.2009.12092005 | I44: S3 매칭(매물 시간·호가 조정) | J44: F2 측정 쟁점 | K44: MLS 시장 | M44: 도서관 전자저널 | N44: 가천대 도서관 로그인 후 DOI 링크로 접속. 구독 안 되면 상호대차 신청
A45: p011 | B45: W07 | C45: 석사② | D45: 박사 | E45: 2012 | F45: Are homes hot or cold potatoes? The distribution of marketing time in the housing market | G45: Regional Science and Urban Economics | H45: https://doi.org/10.1016/j.regsciurbeco.2011.08.010 | I45: S3 매칭(매물 시간·호가 조정) | J45: F2 측정 쟁점 | K45: 비MLS 포털·중개 | M45: 도서관 전자저널 | N45: 가천대 도서관 로그인 후 DOI 링크로 접속. 구독 안 되면 상호대차 신청
A46: p015 | B46: W07 | C46: 박사 | D46: 학부① | E46: 2013 | F46: Days on market and home sales | G46: The RAND Journal of Economics | H46: https://doi.org/10.1111/1756-2171.12022 | I46: S3 매칭(매물 시간·호가 조정) | J46: F2 측정 쟁점 | K46: MLS 시장 | M46: 도서관 전자저널 | N46: 가천대 도서관 로그인 후 DOI 링크로 접속. 구독 안 되면 상호대차 신청
A47: p016 | B47: W07 | C47: 학부① | D47: 학부③ | E47: 2013 | F47: The Probability of Sale and Price Premiums in Withdrawn Auctioned Properties* | G47: Urban Studies | H47: https://doi.org/10.1177/0042098014529341 | I47: S3 매칭(매물 시간·호가 조정) | J47: F2 측정 쟁점 | K47: 경매 시장 | M47: 도서관 전자저널 | N47: 가천대 도서관 로그인 후 DOI 링크로 접속. 구독 안 되면 상호대차 신청
... A114: p080 | B114: W15 | C114: 학부③ | D114: 학부② | E114: 2012 | F114: Trading Volume-Induced Spatial Autocorrelation in Real Estate Prices | G114: The Journal of Real Estate Finance and Economics | H114: https://doi.org/10.1007/s11146-012-9375-y | I114: S4 체결(거래량·가격 발견) | J114: F3 선행성·관계 | K114: 비MLS 포털·중개 (확인) | M114: 무료 원문(직접 받기) | N114: https://link.springer.com/content/pdf/10.1007/s11146-012-9375-y.pdf
A115: p081 | B115: W15 | C115: 이원석 | D115: 학부④ | E115: 2013 | F115: Housing prices and transaction volume | G115: Journal of Housing Economics | H115: https://doi.org/10.1016/j.jhe.2013.02.001 | I115: S4 체결(거래량·가격 발견) | J115: F3 선행성·관계 | K115: MLS 시장 | M115: 받음 | N115: papers/p081.pdf | O115: 받은 파일은 MPRA 워킹페이퍼판. 인용·쪽수는 JHE 게재본으로 다시 확인
A116: p082 | B116: W16 | C116: 박사 | D116: 석사① | E116: 2013 | F116: Price and transaction volume in the Dutch housing market | G116: Regional Science and Urban Economics | H116: https://doi.org/10.1016/j.regsciurbeco.2012.07.002 | I116: S4 체결(거래량·가격 발견) | J116: F3 선행성·관계 | K116: 비MLS 포털·중개 | M116: 받음 | N116: papers/p082.pdf
A117: p083 | B117: W16 | C117: 석사① | D117: 박사 | E117: 2013 | F117: The Relationship between Trading Volume and Purchase Price Index Volatility in Apartment Market | G117: Global Business Administration Review | H117: https://doi.org/10.17092/jibr.2013.10.1.159 | I117: S4 체결(거래량·가격 발견) | J117: F3 선행성·관계 | K117: 비MLS 포털·중개 | M117: 도서관 전자저널 | N117: 가천대 도서관 로그인 후 DOI 링크로 접속. 구독 안 되면 상호대차 신청
A118: p085 | B118: W16 | C118: 석사② | D118: 학부① | E118: 2014 | F118: Ripple effect in house prices and trading volume in the UK housing market: New viewpoint and evidence | G118: Economic Modelling | H118: https://doi.org/10.1016/j.econmod.2014.03.026 | I118: S4 체결(거래량·가격 발견) | J118: F3 선행성·관계 | K118: 비MLS 포털·중개 | M118: 도서관 전자저널 | N118: 가천대 도서관 로그인 후 DOI 링크로 접속. 구독 안 되면 상호대차 신청
...

Sheet 주차별배정
A1: 주차 | B1: 배정일 | C1: 마감 | D1: 담당 | E1: 종류 | F1: pid | G1: 단계 | H1: 기능 | I1: 시장 | J1: 한국 | K1: 제목 | L1: 학술지 | M1: DOI | N1: 짝 | O1: 제출일 | P1: 접수 | Q1: 짝점검 | R1: 반려사유
A2: 예시 | B2: 2026-10-13 | C2: 2026-10-17 | D2: Claude | E2: 예시(정리 완료) | F2: p115 | G2: S4 | H2: F3 | I2: 비MLS 포털·중개 | J2: Y | K2: Frequency domain analysis to detect common cycle in housing price and trading volume | L2: 주택도시금융연구 | M2: 10.38100/jhuf.2021.6.2.53 | N2: 이원석 | O2: 2026-10-13 | P2: O | Q2: O
A3: W01 | B3: 2026-10-19 | C3: 2026-10-23 | D3: 박사 | E3: 파일럿(전원 같은 논문) | F3: p023 | G3: S3 | H3: F1 | I3: 비MLS 포털·중개 | J3: Y | K3: Factors Affecting the Days on Market of Residential Real Estate in Seoul | L3: Korean Association for Housing Policy Studies | M3: 10.24957/hsr.2019.27.1.05 | N3: 전원 비교(원석)
A4: W01 | B4: 2026-10-19 | C4: 2026-10-23 | D4: 석사① | E4: 파일럿(전원 같은 논문) | F4: p023 | G4: S3 | H4: F1 | I4: 비MLS 포털·중개 | J4: Y | K4: Factors Affecting the Days on Market of Residential Real Estate in Seoul | L4: Korean Association for Housing Policy Studies | M4: 10.24957/hsr.2019.27.1.05 | N4: 전원 비교(원석)
A5: W01 | B5: 2026-10-19 | C5: 2026-10-23 | D5: 석사② | E5: 파일럿(전원 같은 논문) | F5: p023 | G5: S3 | H5: F1 | I5: 비MLS 포털·중개 | J5: Y | K5: Factors Affecting the Days on Market of Residential Real Estate in Seoul | L5: Korean Association for Housing Policy Studies | M5: 10.24957/hsr.2019.27.1.05 | N5: 전원 비교(원석)
A6: W01 | B6: 2026-10-19 | C6: 2026-10-23 | D6: 학부① | E6: 파일럿(전원 같은 논문) | F6: p023 | G6: S3 | H6: F1 | I6: 비MLS 포털·중개 | J6: Y | K6: Factors Affecting the Days on Market of Residential Real Estate in Seoul | L6: Korean Association for Housing Policy Studies | M6: 10.24957/hsr.2019.27.1.05 | N6: 전원 비교(원석)
A7: W01 | B7: 2026-10-19 | C7: 2026-10-23 | D7: 학부② | E7: 파일럿(전원 같은 논문) | F7: p023 | G7: S3 | H7: F1 | I7: 비MLS 포털·중개 | J7: Y | K7: Factors Affecting the Days on Market of Residential Real Estate in Seoul | L7: Korean Association for Housing Policy Studies | M7: 10.24957/hsr.2019.27.1.05 | N7: 전원 비교(원석)
A8: W01 | B8: 2026-10-19 | C8: 2026-10-23 | D8: 학부③ | E8: 파일럿(전원 같은 논문) | F8: p023 | G8: S3 | H8: F1 | I8: 비MLS 포털·중개 | J8: Y | K8: Factors Affecting the Days on Market of Residential Real Estate in Seoul | L8: Korean Association for Housing Policy Studies | M8: 10.24957/hsr.2019.27.1.05 | N8: 전원 비교(원석)
A9: W01 | B9: 2026-10-19 | C9: 2026-10-23 | D9: 학부④ | E9: 파일럿(전원 같은 논문) | F9: p023 | G9: S3 | H9: F1 | I9: 비MLS 포털·중개 | J9: Y | K9: Factors Affecting the Days on Market of Residential Real Estate in Seoul | L9: Korean Association for Housing Policy Studies | M9: 10.24957/hsr.2019.27.1.05 | N9: 전원 비교(원석)
A10: W01 | B10: 2026-10-19 | C10: 2026-10-23 | D10: 이원석 | E10: 파일럿(전원 같은 논문) | F10: p023 | G10: S3 | H10: F1 | I10: 비MLS 포털·중개 | J10: Y | K10: Factors Affecting the Days on Market of Residential Real Estate in Seoul | L10: Korean Association for Housing Policy Studies | M10: 10.24957/hsr.2019.27.1.05 | N10: 전원 비교(원석)
A11: W02 | B11: 2026-10-26 | C11: 2026-10-30 | D11: 박사 | E11: 정리 | F11: p089 | G11: S1 | H11: F3 | I11: 비MLS 포털·중개 | J11: Y | K11: A study on the impact of changes in consumer sentiment on the housing market in Korea | L11: International Journal of Urban Sciences | M11: 10.1080/12265934.2016.1239548 | N11: 석사①
A12: W02 | B12: 2026-10-26 | C12: 2026-10-30 | D12: 석사① | E12: 정리 | F12: p092 | G12: S1 | H12: F3 | I12: 비MLS 포털·중개 | J12: Y | K12: Relationship Among News Coverage, Consumers’ Sentiment, Prices, and Trading Volume in Housing Markets | L12: Korean Association for Housing Policy Studies | M12: 10.24957/hsr.2017.25.3.01 | N12: 박사
A13: W02 | B13: 2026-10-26 | C13: 2026-10-30 | D13: 석사② | E13: 정리 | F13: p094 | G13: S1 | H13: F3 | I13: 비MLS 포털·중개 | J13: Y | K13: A Study on the Effects of News Big Data and Google Information Search on Apartment Transaction Volume | L13: Residential Environment Institute Of Korea | M13: 10.22313/reik.2018.16.2.411 | N13: 학부①
A14: W02 | B14: 2026-10-26 | C14: 2026-10-30 | D14: 학부① | E14: 정리 | F14: p103 | G14: S1 | H14: F3 | I14: 비MLS 포털·중개 | J14: Y | K14: Consumer Sentiment in On-line Community and the Variation of Real Estate Market | L14: Residential Environment Institute Of Korea | M14: 10.22313/reik.2019.17.4.31 | N14: 석사②
... A36: W05 | B36: 2026-11-16 | C36: 2026-11-20 | D36: 석사① | E36: 정리 | F36: p129 | G36: S5 | H36: F1 | I36: 비MLS 포털·중개 | J36: Y | K36: Apartment Transaction Volume and Price Volatility: Construction and Application of a Transaction-Volume-Based Price Uncertainty Index | L36: Housing Finance Research | M36: 10.52344/hfr.2026.10.1.133 | N36: 학부②
A37: W05 | B37: 2026-11-16 | C37: 2026-11-20 | D37: 석사② | E37: 정리 | F37: p002 | G37: S3 | H37: F1 | I37: MLS 시장 | K37: The Duration of Marketing Time of Residential Housing | L37: Real Estate Economics | M37: 10.1111/1540-6229.00463 | N37: 박사
A38: W05 | B38: 2026-11-16 | C38: 2026-11-20 | D38: 학부① | E38: 정리 | F38: p003 | G38: S3 | H38: F1 | I38: MLS 시장 | K38: Measuring Residential Real Estate Liquidity | L38: Real Estate Economics | M38: 10.1111/1540-6229.00514 | N38: 학부③
A39: W05 | B39: 2026-11-16 | C39: 2026-11-20 | D39: 학부② | E39: 정리 | F39: p009 | G39: S3 | H39: F1 | I39: MLS 시장 | K39: Liquidating Real Estate Assets Quickly: What Affects the Probability of a Quick Sale? | L39: Journal of Real Estate Practice and Education | M39: 10.1080/10835547.2010.12091669 | N39: 석사①
A40: W05 | B40: 2026-11-16 | C40: 2026-11-20 | D40: 학부③ | E40: 정리 | F40: p012 | G40: S3 | H40: F1 | I40: 비MLS 포털·중개 | K40: Cross sectional Analysis of time on Market indicators for an Australian City | L40: Pacific Rim Property Research Journal | M40: 10.1080/14445921.2012.11104370 | N40: 이원석
A41: W05 | B41: 2026-11-16 | C41: 2026-11-20 | D41: 학부④ | E41: 정리 | F41: p014 | G41: S3 | H41: F1 | I41: 비MLS 포털·중개 | K41: Modelling a property's time to sale by inflating its previous selling price | L41: Journal of the Operational Research Society | M41: 10.1057/jors.2011.74 | N41: 석사②
A42: W05 | B42: 2026-11-16 | C42: 2026-11-20 | D42: 이원석 | E42: 정리 | F42: p019 | G42: S3 | H42: F1 | I42: 비MLS 포털·중개 | K42: Marketing Time and Sales Price of Residential Properties in Akure, Nigeria | L42: Journal of economics and sustainable development | N42: 학부④
A43: W06 | B43: 2026-11-23 | C43: 2026-11-27 | D43: 박사 | E43: 정리 | F43: p105 | G43: S3 | H43: F1 | I43: MLS 시장 | K43: The Repeat Time-On-The-Market Index | L43: Journal of Urban Economics | M43: 10.1016/j.jue.2019.04.005 | N43: 학부①
A44: W06 | B44: 2026-11-23 | C44: 2026-11-27 | D44: 석사① | E44: 정리 | F44: p027 | G44: S3 | H44: F1 | I44: MLS 시장 (확인) | K44: A hybrid neural network for predicting Days on Market a measure of liquidity in real estate industry | L44: Knowledge-Based Systems | M44: 10.1016/j.knosys.2020.106417 | N44: 학부②
A45: W06 | B45: 2026-11-23 | C45: 2026-11-27 | D45: 석사② | E45: 정리 | F45: p028 | G45: S3 | H45: F1 | I45: 비MLS 포털·중개 | K45: Key determinants of time on the market: an analysis of residential housing market in Sri Lanka | L45: International Journal of Housing Markets and Analysis | M45: 10.1108/ijhma-06-2020-0071 | N45: 박사
A46: W06 | B46: 2026-11-23 | C46: 2026-11-27 | D46: 학부① | E46: 정리 | F46: p032 | G46: S3 | H46: F1 | I46: 비MLS 포털·중개 | K46: The Impacts of Property Features on Time on Market of Real Estate Assets in Lagos Metropolis, Nigeria | L46: UNIOSUN Journal of Engineering and Environmental Sciences | M46: 10.36108/ujees/2202.40.0210 | N46: 학부③
A47: W06 | B47: 2026-11-23 | C47: 2026-11-27 | D47: 학부② | E47: 정리 | F47: p004 | G47: S3 | H47: F2 | I47: MLS 시장 | K47: Censored Sample Bias, Macroeconomic Factors, and Time on Market of Residential Housing | L47: Journal of Real Estate Research | M47: 10.1080/10835547.1994.12090750 | N47: 석사①
A48: W06 | B48: 2026-11-23 | C48: 2026-11-27 | D48: 학부③ | E48: 정리 | F48: p005 | G48: S3 | H48: F2 | I48: 비MLS 포털·중개 (확인) | K48: Exploring Spatial Effects on Urban Housing Duration | L48: Environment and Planning A Economy and Space | M48: 10.1068/a35170 | N48: 이원석
A49: W06 | B49: 2026-11-23 | C49: 2026-11-27 | D49: 학부④ | E49: 정리 | F49: p006 | G49: S3 | H49: F2 | I49: 비MLS 포털·중개 | K49: Submarket Dynamics of Time to Sale | L49: Real Estate Economics | M49: 10.1111/j.1540-6229.2006.00171.x | N49: 석사②
A50: W06 | B50: 2026-11-23 | C50: 2026-11-27 | D50: 이원석 | E50: 정리 | F50: p007 | G50: S3 | H50: F2 | I50: MLS 시장 | K50: The Probability of Sale for Residential Real Estate | L50: Journal of Housing Research | M50: 10.1080/10835547.2007.12091978 | N50: 학부④
A51: W07 | B51: 2026-11-30 | C51: 2026-12-04 | D51: 박사 | E51: 정리 | F51: p015 | G51: S3 | H51: F2 | I51: MLS 시장 | K51: Days on market and home sales | L51: The RAND Journal of Economics | M51: 10.1111/1756-2171.12022 | N51: 학부①
A52: W07 | B52: 2026-11-30 | C52: 2026-12-04 | D52: 석사① | E52: 정리 | F52: p008 | G52: S3 | H52: F2 | I52: MLS 시장 | K52: Spatial Heterogeneity in Listing Duration: The Influence of Relative Location to Marketability | L52: Journal of Housing Research | M52: 10.1080/10835547.2009.12092005 | N52: 학부②
A53: W07 | B53: 2026-11-30 | C53: 2026-12-04 | D53: 석사② | E53: 정리 | F53: p011 | G53: S3 | H53: F2 | I53: 비MLS 포털·중개 | K53: Are homes hot or cold potatoes? The distribution of marketing time in the housing market | L53: Regional Science and Urban Economics | M53: 10.1016/j.regsciurbeco.2011.08.010 | N53: 박사
A54: W07 | B54: 2026-11-30 | C54: 2026-12-04 | D54: 학부① | E54: 정리 | F54: p016 | G54: S3 | H54: F2 | I54: 경매 시장 | K54: The Probability of Sale and Price Premiums in Withdrawn Auctioned Properties* | L54: Urban Studies | M54: 10.1177/0042098014529341 | N54: 학부③
... A156: W20 | B156: 2027-03-01 | C156: 2027-03-05 | D156: 석사① | E156: 정리 | F156: p146 | G156: S1 | H156: F3 | I156: 비MLS 포털·중개 | K156: From digital search to deed: forecasting UK housing purchases in Spain using Google Trends across the Brexit divide | L156: Journal of European Real Estate Research | M156: 10.1108/jerer-07-2025-0060 | N156: 학부②

Sheet 진행현황
A1: 주차 | B1: 배정 | C1: 제출 | D1: 통과(O) | E1: 반려 | F1: 짝점검 완료 | G1: 통과율
A2: W01 | B2: =COUNTIF(주차별배정!$A$3:$A$156,A2) -> 8 | C2: =COUNTIFS(주차별배정!$A$3:$A$156,A2,주차별배정!$O$3:$O$156,"<>") -> 0 | D2: =COUNTIFS(주차별배정!$A$3:$A$156,A2,주차별배정!$P$3:$P$156,"O") -> 0 | E2: =COUNTIFS(주차별배정!$A$3:$A$156,A2,주차별배정!$P$3:$P$156,"반려") -> 0 | F2: =COUNTIFS(주차별배정!$A$3:$A$156,A2,주차별배정!$Q$3:$Q$156,"<>") -> 0 | G2: =IF(C2=0,"-",D2/C2) -> -
A3: W02 | B3: =COUNTIF(주차별배정!$A$3:$A$156,A3) -> 8 | C3: =COUNTIFS(주차별배정!$A$3:$A$156,A3,주차별배정!$O$3:$O$156,"<>") -> 0 | D3: =COUNTIFS(주차별배정!$A$3:$A$156,A3,주차별배정!$P$3:$P$156,"O") -> 0 | E3: =COUNTIFS(주차별배정!$A$3:$A$156,A3,주차별배정!$P$3:$P$156,"반려") -> 0 | F3: =COUNTIFS(주차별배정!$A$3:$A$156,A3,주차별배정!$Q$3:$Q$156,"<>") -> 0 | G3: =IF(C3=0,"-",D3/C3) -> -
A4: W03 | B4: =COUNTIF(주차별배정!$A$3:$A$156,A4) -> 8 | C4: =COUNTIFS(주차별배정!$A$3:$A$156,A4,주차별배정!$O$3:$O$156,"<>") -> 0 | D4: =COUNTIFS(주차별배정!$A$3:$A$156,A4,주차별배정!$P$3:$P$156,"O") -> 0 | E4: =COUNTIFS(주차별배정!$A$3:$A$156,A4,주차별배정!$P$3:$P$156,"반려") -> 0 | F4: =COUNTIFS(주차별배정!$A$3:$A$156,A4,주차별배정!$Q$3:$Q$156,"<>") -> 0 | G4: =IF(C4=0,"-",D4/C4) -> -
A5: W04 | B5: =COUNTIF(주차별배정!$A$3:$A$156,A5) -> 8 | C5: =COUNTIFS(주차별배정!$A$3:$A$156,A5,주차별배정!$O$3:$O$156,"<>") -> 0 | D5: =COUNTIFS(주차별배정!$A$3:$A$156,A5,주차별배정!$P$3:$P$156,"O") -> 0 | E5: =COUNTIFS(주차별배정!$A$3:$A$156,A5,주차별배정!$P$3:$P$156,"반려") -> 0 | F5: =COUNTIFS(주차별배정!$A$3:$A$156,A5,주차별배정!$Q$3:$Q$156,"<>") -> 0 | G5: =IF(C5=0,"-",D5/C5) -> -
A6: W05 | B6: =COUNTIF(주차별배정!$A$3:$A$156,A6) -> 8 | C6: =COUNTIFS(주차별배정!$A$3:$A$156,A6,주차별배정!$O$3:$O$156,"<>") -> 0 | D6: =COUNTIFS(주차별배정!$A$3:$A$156,A6,주차별배정!$P$3:$P$156,"O") -> 0 | E6: =COUNTIFS(주차별배정!$A$3:$A$156,A6,주차별배정!$P$3:$P$156,"반려") -> 0 | F6: =COUNTIFS(주차별배정!$A$3:$A$156,A6,주차별배정!$Q$3:$Q$156,"<>") -> 0 | G6: =IF(C6=0,"-",D6/C6) -> -
A7: W06 | B7: =COUNTIF(주차별배정!$A$3:$A$156,A7) -> 8 | C7: =COUNTIFS(주차별배정!$A$3:$A$156,A7,주차별배정!$O$3:$O$156,"<>") -> 0 | D7: =COUNTIFS(주차별배정!$A$3:$A$156,A7,주차별배정!$P$3:$P$156,"O") -> 0 | E7: =COUNTIFS(주차별배정!$A$3:$A$156,A7,주차별배정!$P$3:$P$156,"반려") -> 0 | F7: =COUNTIFS(주차별배정!$A$3:$A$156,A7,주차별배정!$Q$3:$Q$156,"<>") -> 0 | G7: =IF(C7=0,"-",D7/C7) -> -
A8: W07 | B8: =COUNTIF(주차별배정!$A$3:$A$156,A8) -> 8 | C8: =COUNTIFS(주차별배정!$A$3:$A$156,A8,주차별배정!$O$3:$O$156,"<>") -> 0 | D8: =COUNTIFS(주차별배정!$A$3:$A$156,A8,주차별배정!$P$3:$P$156,"O") -> 0 | E8: =COUNTIFS(주차별배정!$A$3:$A$156,A8,주차별배정!$P$3:$P$156,"반려") -> 0 | F8: =COUNTIFS(주차별배정!$A$3:$A$156,A8,주차별배정!$Q$3:$Q$156,"<>") -> 0 | G8: =IF(C8=0,"-",D8/C8) -> -
A9: W08 | B9: =COUNTIF(주차별배정!$A$3:$A$156,A9) -> 8 | C9: =COUNTIFS(주차별배정!$A$3:$A$156,A9,주차별배정!$O$3:$O$156,"<>") -> 0 | D9: =COUNTIFS(주차별배정!$A$3:$A$156,A9,주차별배정!$P$3:$P$156,"O") -> 0 | E9: =COUNTIFS(주차별배정!$A$3:$A$156,A9,주차별배정!$P$3:$P$156,"반려") -> 0 | F9: =COUNTIFS(주차별배정!$A$3:$A$156,A9,주차별배정!$Q$3:$Q$156,"<>") -> 0 | G9: =IF(C9=0,"-",D9/C9) -> -
A10: W09 | B10: =COUNTIF(주차별배정!$A$3:$A$156,A10) -> 8 | C10: =COUNTIFS(주차별배정!$A$3:$A$156,A10,주차별배정!$O$3:$O$156,"<>") -> 0 | D10: =COUNTIFS(주차별배정!$A$3:$A$156,A10,주차별배정!$P$3:$P$156,"O") -> 0 | E10: =COUNTIFS(주차별배정!$A$3:$A$156,A10,주차별배정!$P$3:$P$156,"반려") -> 0 | F10: =COUNTIFS(주차별배정!$A$3:$A$156,A10,주차별배정!$Q$3:$Q$156,"<>") -> 0 | G10: =IF(C10=0,"-",D10/C10) -> -
A11: W10 | B11: =COUNTIF(주차별배정!$A$3:$A$156,A11) -> 8 | C11: =COUNTIFS(주차별배정!$A$3:$A$156,A11,주차별배정!$O$3:$O$156,"<>") -> 0 | D11: =COUNTIFS(주차별배정!$A$3:$A$156,A11,주차별배정!$P$3:$P$156,"O") -> 0 | E11: =COUNTIFS(주차별배정!$A$3:$A$156,A11,주차별배정!$P$3:$P$156,"반려") -> 0 | F11: =COUNTIFS(주차별배정!$A$3:$A$156,A11,주차별배정!$Q$3:$Q$156,"<>") -> 0 | G11: =IF(C11=0,"-",D11/C11) -> -
A12: W11 | B12: =COUNTIF(주차별배정!$A$3:$A$156,A12) -> 8 | C12: =COUNTIFS(주차별배정!$A$3:$A$156,A12,주차별배정!$O$3:$O$156,"<>") -> 0 | D12: =COUNTIFS(주차별배정!$A$3:$A$156,A12,주차별배정!$P$3:$P$156,"O") -> 0 | E12: =COUNTIFS(주차별배정!$A$3:$A$156,A12,주차별배정!$P$3:$P$156,"반려") -> 0 | F12: =COUNTIFS(주차별배정!$A$3:$A$156,A12,주차별배정!$Q$3:$Q$156,"<>") -> 0 | G12: =IF(C12=0,"-",D12/C12) -> -
A13: W12 | B13: =COUNTIF(주차별배정!$A$3:$A$156,A13) -> 8 | C13: =COUNTIFS(주차별배정!$A$3:$A$156,A13,주차별배정!$O$3:$O$156,"<>") -> 0 | D13: =COUNTIFS(주차별배정!$A$3:$A$156,A13,주차별배정!$P$3:$P$156,"O") -> 0 | E13: =COUNTIFS(주차별배정!$A$3:$A$156,A13,주차별배정!$P$3:$P$156,"반려") -> 0 | F13: =COUNTIFS(주차별배정!$A$3:$A$156,A13,주차별배정!$Q$3:$Q$156,"<>") -> 0 | G13: =IF(C13=0,"-",D13/C13) -> -
... A21: W20 | B21: =COUNTIF(주차별배정!$A$3:$A$156,A21) -> 2 | C21: =COUNTIFS(주차별배정!$A$3:$A$156,A21,주차별배정!$O$3:$O$156,"<>") -> 0 | D21: =COUNTIFS(주차별배정!$A$3:$A$156,A21,주차별배정!$P$3:$P$156,"O") -> 0 | E21: =COUNTIFS(주차별배정!$A$3:$A$156,A21,주차별배정!$P$3:$P$156,"반려") -> 0 | F21: =COUNTIFS(주차별배정!$A$3:$A$156,A21,주차별배정!$Q$3:$Q$156,"<>") -> 0 | G21: =IF(C21=0,"-",D21/C21) -> -
A22: 합계 | B22: =SUM(B2:B21) -> 154 | C22: =SUM(C2:C21) -> 0 | D22: =SUM(D2:D21) -> 0 | E22: =SUM(E2:E21) -> 0 | F22: =SUM(F2:F21) -> 0 | G22: =IF(C22=0,"-",D22/C22) -> -
A24: W01 파일럿은 같은 논문을 8명이 정리하므로 배정 8건으로 센다. 예시 p115는 Claude가 정리했고 원석이 검증한다.

Sheet 분류틀
A1: 분류 틀: 단계(주축) × 기능(절 내부) × 시장(교차)
A3: 코드 | B3: 뜻 | C3: 대표 지표
A4: S1 수요·관심 | B4: 잠재 수요 신호 | C4: 검색량, 뉴스·소비 심리, 조회수
A5: S2 공급·호가 설정 | B5: 공급 쪽 깊이 | C5: 신규 매물·재고·흡수율, 호가 수준·호가 지수
A6: S3 매칭 | B6: 즉시성(시간) | C6: TOM/DOM, 매각확률, 호가 인하
A7: S4 체결·가격 발견 | B7: 비용·깊이 | C7: 거래량·회전율, sale-to-list, 호가–체결 격차
A8: S5 집계 상태 | B8: 복합 | C8: tightness·heat, 유동성 지수
A9: F1 정의·구축 | B9: 지표를 정의하거나 만드는 논문
A10: F2 측정 쟁점 | B10: 절단·철회·재등록·집계 단위를 다루는 논문
A11: F3 선행성·관계 | B11: 지표가 가격·거래량을 앞서는지, 지표끼리의 관계
A12: 시장 | B12: MLS / 비MLS 포털·중개 / 경매 / 복수 | C12: '(확인)'이 붙은 것은 전문을 보고 정한다
A14: 교차표: 단계 × 시장, 단계 × 기능 (종합148 시트에서 자동 계산)
A15: 단계 | B15: MLS 시장 | C15: 비MLS 포털·중개 | D15: 경매 시장 | E15: 복수/불명 | F15: 합계 | G15: F1 | H15: F2 | I15: F3
A16: S1 수요·관심 | B16: =COUNTIFS(종합148!$I$2:$I$149,$A16,종합148!$K$2:$K$149,B$15&"*") -> 7 | C16: =COUNTIFS(종합148!$I$2:$I$149,$A16,종합148!$K$2:$K$149,C$15&"*") -> 16 | D16: =COUNTIFS(종합148!$I$2:$I$149,$A16,종합148!$K$2:$K$149,D$15&"*") -> 1 | E16: =COUNTIFS(종합148!$I$2:$I$149,$A16,종합148!$K$2:$K$149,E$15&"*") -> 1 | F16: =SUM(B16:E16) -> 25 | G16: =COUNTIFS(종합148!$I$2:$I$149,$A16,종합148!$J$2:$J$149,"F1*") -> 4 | H16: =COUNTIFS(종합148!$I$2:$I$149,$A16,종합148!$J$2:$J$149,"F2*") -> 0 | I16: =COUNTIFS(종합148!$I$2:$I$149,$A16,종합148!$J$2:$J$149,"F3*") -> 21
A17: S2 공급·호가 설정 | B17: =COUNTIFS(종합148!$I$2:$I$149,$A17,종합148!$K$2:$K$149,B$15&"*") -> 4 | C17: =COUNTIFS(종합148!$I$2:$I$149,$A17,종합148!$K$2:$K$149,C$15&"*") -> 10 | D17: =COUNTIFS(종합148!$I$2:$I$149,$A17,종합148!$K$2:$K$149,D$15&"*") -> 2 | E17: =COUNTIFS(종합148!$I$2:$I$149,$A17,종합148!$K$2:$K$149,E$15&"*") -> 0 | F17: =SUM(B17:E17) -> 16 | G17: =COUNTIFS(종합148!$I$2:$I$149,$A17,종합148!$J$2:$J$149,"F1*") -> 7 | H17: =COUNTIFS(종합148!$I$2:$I$149,$A17,종합148!$J$2:$J$149,"F2*") -> 3 | I17: =COUNTIFS(종합148!$I$2:$I$149,$A17,종합148!$J$2:$J$149,"F3*") -> 6
A18: S3 매칭(매물 시간·호가 조정) | B18: =COUNTIFS(종합148!$I$2:$I$149,$A18,종합148!$K$2:$K$149,B$15&"*") -> 20 | C18: =COUNTIFS(종합148!$I$2:$I$149,$A18,종합148!$K$2:$K$149,C$15&"*") -> 18 | D18: =COUNTIFS(종합148!$I$2:$I$149,$A18,종합148!$K$2:$K$149,D$15&"*") -> 1 | E18: =COUNTIFS(종합148!$I$2:$I$149,$A18,종합148!$K$2:$K$149,E$15&"*") -> 0 | F18: =SUM(B18:E18) -> 39 | G18: =COUNTIFS(종합148!$I$2:$I$149,$A18,종합148!$J$2:$J$149,"F1*") -> 13 | H18: =COUNTIFS(종합148!$I$2:$I$149,$A18,종합148!$J$2:$J$149,"F2*") -> 17 | I18: =COUNTIFS(종합148!$I$2:$I$149,$A18,종합148!$J$2:$J$149,"F3*") -> 9
A19: S4 체결(거래량·가격 발견) | B19: =COUNTIFS(종합148!$I$2:$I$149,$A19,종합148!$K$2:$K$149,B$15&"*") -> 15 | C19: =COUNTIFS(종합148!$I$2:$I$149,$A19,종합148!$K$2:$K$149,C$15&"*") -> 35 | D19: =COUNTIFS(종합148!$I$2:$I$149,$A19,종합148!$K$2:$K$149,D$15&"*") -> 0 | E19: =COUNTIFS(종합148!$I$2:$I$149,$A19,종합148!$K$2:$K$149,E$15&"*") -> 2 | F19: =SUM(B19:E19) -> 52 | G19: =COUNTIFS(종합148!$I$2:$I$149,$A19,종합148!$J$2:$J$149,"F1*") -> 6 | H19: =COUNTIFS(종합148!$I$2:$I$149,$A19,종합148!$J$2:$J$149,"F2*") -> 6 | I19: =COUNTIFS(종합148!$I$2:$I$149,$A19,종합148!$J$2:$J$149,"F3*") -> 40
A20: S5 집계 상태·지수 | B20: =COUNTIFS(종합148!$I$2:$I$149,$A20,종합148!$K$2:$K$149,B$15&"*") -> 7 | C20: =COUNTIFS(종합148!$I$2:$I$149,$A20,종합148!$K$2:$K$149,C$15&"*") -> 8 | D20: =COUNTIFS(종합148!$I$2:$I$149,$A20,종합148!$K$2:$K$149,D$15&"*") -> 0 | E20: =COUNTIFS(종합148!$I$2:$I$149,$A20,종합148!$K$2:$K$149,E$15&"*") -> 1 | F20: =SUM(B20:E20) -> 16 | G20: =COUNTIFS(종합148!$I$2:$I$149,$A20,종합148!$J$2:$J$149,"F1*") -> 9 | H20: =COUNTIFS(종합148!$I$2:$I$149,$A20,종합148!$J$2:$J$149,"F2*") -> 0 | I20: =COUNTIFS(종합148!$I$2:$I$149,$A20,종합148!$J$2:$J$149,"F3*") -> 7
A21: 합계 | B21: =SUM(B16:B20) -> 53 | C21: =SUM(C16:C20) -> 87 | D21: =SUM(D16:D20) -> 4 | E21: =SUM(E16:E20) -> 4 | F21: =SUM(F16:F20) -> 148 | G21: =SUM(G16:G20) -> 39 | H21: =SUM(H16:H20) -> 26 | I21: =SUM(I16:I20) -> 83

Sheet 선별과정
A1: 52,006건에서 148편까지 (PRISMA 2020)
A3: 단계 | B3: 건수 | C3: 무엇을 했나
A4: 식별: Semantic Scholar 검색 | B4: 4351 | C4: 블록 ①②③ 불리언 검색, 1986년 이후
A5: 식별: Crossref 검색 | B5: 16800 | C5: 28개 구문 × 관련도 상위 600
A6: 식별: 핵심 학술지 16종 전수 | B6: 26581 | C6: REE·JREFE·JHE·JUE 등 1986년 이후 모든 논문
A7: 식별: 인용 추적 | B7: 876 | C7: 핵심 5편을 인용한 논문
A8: 식별: OpenAlex 보완 검색 | B8: 3398 | C8: 제목·초록 불리언, API 키 사용
A9: 식별 합계 | B9: =SUM(B4:B8) -> 52006 | C9: 위 다섯 줄의 합
A10: 중복 제거 후 | B10: 37104 | C10: DOI·제목으로 같은 논문 합침
A11: 제목·초록 판독 | B11: 1400 | C11: 규칙(주택 맥락어+유동성 지표어)을 통과한 것을 한 편씩 읽음
A12: 제목·초록 통과 | B12: 438 | C12: 주거용 매매시장, 학술지, 유동성 지표를 다룸
A13: → 배경(이론 모형) | B13: 37 | C13: 서론에서 인용만
A14: → 증거지도 | B14: 253 | C14: 지표를 다른 요인의 결과변수로만 씀. 건수 그림만
A15: → 종합 대상 | B15: 148 | C15: 지표 자체가 연구 대상. 교수 승인 2026-10-11
A16: 확인: 배경+증거지도+종합 | B16: =B13+B14+B15 -> 438 | C16: =IF(B16=B12,"438과 일치","불일치") -> 438과 일치
A17: 출처 | C17: 저장소 review/prisma_flow.md (2026-10-10 실행)

Sheet 전체438
A1: 구분 | B1: pid | C1: 연도 | D1: 제목 | E1: 학술지 | F1: DOI | G1: 지표층 | H1: 상태
A2: 종합 | B2: p001 | C2: 1987 | D2: An Investigation of the Major Influences of Residential Liquidity: A Multivariate Approach | E2: Real Estate Economics | F2: 10.1111/1540-6229.00410 | G2: A/C | H2: I
A3: 종합 | B3: p002 | C3: 1988 | D3: The Duration of Marketing Time of Residential Housing | E3: Real Estate Economics | F3: 10.1111/1540-6229.00463 | G3: A | H3: I
A4: 종합 | B4: p003 | C4: 1990 | D4: Measuring Residential Real Estate Liquidity | E4: Real Estate Economics | F4: 10.1111/1540-6229.00514 | G4: A | H4: I
A5: 종합 | B5: p004 | C5: 1994 | D5: Censored Sample Bias, Macroeconomic Factors, and Time on Market of Residential Housing | E5: Journal of Real Estate Research | F5: 10.1080/10835547.1994.12090750 | G5: A | H5: I
A6: 종합 | B6: p005 | C6: 2003 | D6: Exploring Spatial Effects on Urban Housing Duration | E6: Environment and Planning A Economy and Space | F6: 10.1068/a35170 | G6: A | H6: I
A7: 종합 | B7: p006 | C7: 2006 | D7: Submarket Dynamics of Time to Sale | E7: Real Estate Economics | F7: 10.1111/j.1540-6229.2006.00171.x | G7: A | H7: I
A8: 종합 | B8: p007 | C8: 2007 | D8: The Probability of Sale for Residential Real Estate | E8: Journal of Housing Research | F8: 10.1080/10835547.2007.12091978 | G8: A | H8: I
A9: 종합 | B9: p008 | C9: 2009 | D9: Spatial Heterogeneity in Listing Duration: The Influence of Relative Location to Marketability | E9: Journal of Housing Research | F9: 10.1080/10835547.2009.12092005 | G9: A | H9: I
A10: 종합 | B10: p009 | C10: 2010 | D10: Liquidating Real Estate Assets Quickly: What Affects the Probability of a Quick Sale? | E10: Journal of Real Estate Practice and Education | F10: 10.1080/10835547.2010.12091669 | G10: A | H10: I
A11: 종합 | B11: p010 | C11: 2011 | D11: Housing price, trading volume and time on market [title garbled in source; verify in IRER 2011] | E11: International Real Estate Review | F11: 10.53383/100144 | G11: A/C | H11: I
A12: 종합 | B12: p011 | C12: 2012 | D12: Are homes hot or cold potatoes? The distribution of marketing time in the housing market | E12: Regional Science and Urban Economics | F12: 10.1016/j.regsciurbeco.2011.08.010 | G12: A | H12: I
A13: 종합 | B13: p012 | C13: 2012 | D13: Cross sectional Analysis of time on Market indicators for an Australian City | E13: Pacific Rim Property Research Journal | F13: 10.1080/14445921.2012.11104370 | G13: A/C | H13: I
... A19: 종합 | B19: p018 | C19: 2015 | D19: For sale… but for how long? a methodological proposal for estimating time-on-the-market | E19: International Journal of Strategic Property Management | F19: 10.3846/1648715x.2015.1072746 | G19: A | H19: I
A20: 종합 | B20: p019 | C20: 2015 | D20: Marketing Time and Sales Price of Residential Properties in Akure, Nigeria | E20: Journal of economics and sustainable development | G20: A | H20: I
A21: 종합 | B21: p020 | C21: 2015 | D21: The Effect of Relisting on House Selling Price | E21: Journal of real estate finance and economics | F21: 10.1007/s11146-015-9503-6 | G21: A | H21: I
A22: 종합 | B22: p021 | C22: 2016 | D22: A Spatiotemporal Solution for the Simultaneous Sale Price and Time‐on‐the‐Market Problem | E22: Real Estate Economics | F22: 10.1111/1540-6229.12121 | G22: A | H22: I
A23: 종합 | B23: p022 | C23: 2016 | D23: Measuring the influence of space and time effects on time on the market | E23: Urban Studies | F23: 10.1177/0042098015596923 | G23: A | H23: I
A24: 종합 | B24: p023 | C24: 2019 | D24: Factors Affecting the Days on Market of Residential Real Estate in Seoul | E24: Korean Association for Housing Policy Studies | F24: 10.24957/hsr.2019.27.1.05 | G24: A | H24: I
A25: 종합 | B25: p024 | C25: 2019 | D25: Liquidity Imbalance in the Residential Real Estate Market | E25: Journal of Housing Research | F25: 10.1080/10527001.2020.1776513 | G25: A/C | H25: I
A26: 종합 | B26: p025 | C26: 2019 | D26: The Effect of Apartment Housing Characteristics on the Days On Market(DOM) | E26: The Korean Association of Urban Policies | F26: 10.21447/jup.2019.10.3.101 | G26: A | H26: I
A27: 종합 | B27: p026 | C27: 2019 | D27: The influence of house, seller, and locational factors on the probability of sale | E27: Journal of Housing Economics | F27: 10.1016/j.jhe.2018.09.009 | G27: A | H27: I
A28: 종합 | B28: p027 | C28: 2020 | D28: A hybrid neural network for predicting Days on Market a measure of liquidity in real estate industry | E28: Knowledge-Based Systems | F28: 10.1016/j.knosys.2020.106417 | G28: A | H28: I
A29: 종합 | B29: p028 | C29: 2020 | D29: Key determinants of time on the market: an analysis of residential housing market in Sri Lanka | E29: International Journal of Housing Markets and Analysis | F29: 10.1108/ijhma-06-2020-0071 | G29: A | H29: I
A30: 종합 | B30: p029 | C30: 2020 | D30: Solving Old Puzzles with New Tricks: Addressing Endogeneity and Nonlinearity in Time-on-Market Research | E30: Journal of Real Estate Research | F30: 10.1080/08965803.2020.1844476 | G30: A | H30: I
A31: 종합 | B31: p030 | C31: 2021 | D31: Average time to sell a property and credit conditions: Evidence from the Italian housing market survey | E31: Bulletin of Economic Research | F31: 10.1111/boer.12284 | G31: A | H31: I
A32: 종합 | B32: p031 | C32: 2021 | D32: Time on the Market and Probability of Sale Using a Generalized Geometric Hazard Model | E32: Journal of Econometric Methods | F32: 10.1515/jem-2020-0017 | G32: A | H32: I
... A149: 종합 | B149: p148 | C149: 2026 | D149: Real Estate News Data by Living District in Seoul Trend Analysis Research Through Topic Modeling and Sentiment Analysis: Focusing on Apartment and Non-Apartment Transaction Volume | E149: 정보과학회 컴퓨팅의 실제 논문지 | F149: 10.5626/ktcp.2026.32.3.89 | G149: D | H149: I
A150: 배경(이론) | C150: 1988 | D150: Price Strategies for Idiosyncratic Goods—The Case of Housing | E150: Real Estate Economics | F150: 10.1111/1540-6229.00462 | G150: T | H150: I
A151: 배경(이론) | C151: 1992 | D151: A Simple Search and Bargaining Model of Real Estate Markets | E151: Real Estate Economics | F151: 10.1111/1540-6229.00595 | G151: T | H151: I
A152: 배경(이론) | C152: 1994 | D152: Contigent Price Contracts and the Efficiency of Housing Markets | E152: Real Estate Economics | F152: 10.1111/1540-6229.00650 | G152: T | H152: I
A153: 배경(이론) | C153: 1995 | D153: Prices and Trading Volume in the Housing Market: A Model with Down-Payment Effects | E153: Quarterly Journal of Economics | F153: 10.2307/2118444 | G153: T | H153: I
A154: 배경(이론) | C154: 1999 | D154: Time-on-the-Market as a Sign of Quality | E154: Review of Economic Studies | F154: 10.1111/1467-937x.00098 | G154: T | H154: I
A155: 배경(이론) | C155: 2001 | D155: A Theory of Liquidity in Residential Real Estate Markets | E155: Journal of Urban Economics | F155: 10.1006/juec.2000.2180 | G155: T | H155: I
A156: 배경(이론) | C156: 2004 | D156: Efficiency of Housing Market | E156: The Japanese Journal of Real Estate Sciences | F156: 10.5736/jares1985.18.22 | G156: C/T | H156: I?
A157: 배경(이론) | C157: 2008 | D157: Real Estate Returns and Risk with Heterogeneous Investors | E157: Real Estate Economics | F157: 10.1111/j.1540-6229.2008.00229.x | G157: T | H157: I
A158: 배경(이론) | C158: 2009 | D158: House Prices, Sales and Time on the Market: A Search-Theoretic Framework | E158: International Economic Review | F158: 10.1111/iere.12019 | G158: T | H158: I
A159: 배경(이론) | C159: 2011 | D159: A Disequilibrium Model of the Market for Houses: Implicit Selling Time as a Signal of Optimal Holding Periods and Buyer Valuation | E159: Urban Studies | F159: 10.1177/0042098010385156 | G159: T | H159: I
A160: 배경(이론) | C160: 2011 | D160: The Determination Of Optimal Reservation Price Setting For Homeowners | E160: Journal of Business & Economics Research (JBER) | F160: 10.19030/jber.v2i7.2896 | G160: T | H160: I?
A161: 배경(이론) | C161: 2012 | D161: Why Do Sellers Hold Out in the Housing Market? An Option‐Based Explanation | E161: Real Estate Economics | F161: 10.1111/j.1540-6229.2012.00345.x | G161: T | H161: I
...
